Workbook
Name a: #REF!
Name a: #REF!
Name a: #REF!
Name a: #REF!
Name a: #REF!
Name a: #REF!
Name a: #REF!
Name a: #REF!
Name a: #REF!
Name a: #REF!
Name a: #REF!
Name a: #REF!
Name a: #REF!
Name a: #REF!
Name aaa: #REF!
Name aaa: #REF!
Name aaa: #REF!
Name aaa: #REF!
Name aaa: #REF!
Name aaa: #REF!
Name aaaaaa: #REF!
Name aaaaaa: #REF!
Name aaaaaa: #REF!
Name aaaaaa: #REF!
Name aaaaaa: #REF!
Name aaaaaa: #REF!
Name aaaaaa: #REF!
Name aaaaaa: #REF!
Name aaaaaa: #REF!
Name aaaaaa: #REF!
Name aaaaaa: #REF!
Name aaaaaa: #REF!
Name aaaaaa: #REF!
Name aaaaaa: #REF!
Name AAAAAAAAAAA: #REF!
Name AAAAAAAAAAA: #REF!
Name AAAAAAAAAAA: #REF!
Name AAAAAAAAAAA: #REF!
Name AAAAAAAAAAA: #REF!
Name AAAAAAAAAAA: #REF!
Name AAAAAAAAAAA: #REF!
Name AAAAAAAAAAA: #REF!
Name AAAAAAAAAAA: #REF!
Name AAAAAAAAAAA: #REF!
Name AAAAAAAAAAA: #REF!
Name AAAAAAAAAAA: #REF!
Name AAAAAAAAAAA: #REF!
Name AAAAAAAAAAA: #REF!
Name bb: #REF!
Name bb: #REF!
Name bb: #REF!
Name bb: #REF!
Name bb: #REF!
Name bb: #REF!
Name bb: #REF!
Name bb: #REF!
Name bb: #REF!
Name bb: #REF!
Name bb: #REF!
Name bb: #REF!

Sheet PG
A1: République Islamique de Mauritanie | H1: الجمهورية الإسلامية الموريتانية
A2: Honneur - Fraternité - Justice | H2: شرف -إخاء -عدالة
A3: Ministère des Finances | G3: وزارة المالية
A4: Direction Générale du Trésor et de la Comptabilité Publique | G4: المديرية العامة للخزينة و المحاسبة العمومية
A6: Direction de l'Audit et du Contrôle Interne | H6: إدارة التدقيق و الرقابة الداخلية
A12: RAPPORT DE VERIFICATION
A17: PERCEPTION De ADEL BAGROU
A20: POUR LA PERIODE DU 21/07/2023 AU 31/12/2023
H28: 45293

Sheet DEPUILLEMENT 
A1: Republique Islamique de Mauritanie
A2: Ministère des Finances
A3: Direction Générale du Trésor et de la Comptabilité Publique
A4: Direction de l'Audit et du Contrôle Interne
A6: Poste Comptable: Perception d'Adel Begrou
A9: DEPUILLEMENT DES RECETTES DU 01/01/2024 au 15/05/2024
A11: N° Quittance | B11: Autres recettes non fiscales diverses | C11: ITS | D11: TVA | E11: IMF | F11: CNAM | G11: CNSS | H11: Timbres mobiles | I11: CNI | J11: Extrai | K11: Amendes F | L11: Fonds d'Intervention pour l'environnement | M11: C. Adel Bagrou | N11: C. El Masgoule | O11: C. Seivane | P11: Réception de fonds | Q11: Total général
Q12: =SUM(B12:P12) -> 0
Q13: =SUM(B13:P13) -> 0
Q14: =SUM(B14:P14) -> 0
Q15: =SUM(B15:P15) -> 0
Q16: =SUM(B16:P16) -> 0
Q17: =SUM(B17:P17) -> 0
Q18: =SUM(B18:P18) -> 0
Q19: =SUM(B19:P19) -> 0
Q20: =SUM(B20:P20) -> 0
Q21: =SUM(B21:P21) -> 0
Q22: =SUM(B22:P22) -> 0
Q23: =SUM(B23:P23) -> 0
... Q59: =SUM(B59:P59) -> 0
A60: TOTAUX | B60: =SUM(B12:B59) -> 0 | C60: =SUM(C12:C59) -> 0 | D60: =SUM(D12:D59) -> 0 | E60: =SUM(E12:E59) -> 0 | F60: =SUM(F12:F59) -> 0 | G60: =SUM(G12:G59) -> 0 | H60: =SUM(H12:H59) -> 0 | I60: =SUM(I12:I59) -> 0 | ... Q60: =SUM(Q12:Q59) -> 0
A63: RECAP | B63: Autres recettes non fiscales diverses | C63: ITS | D63: TVA | E63: IMF | F63: CNAM | G63: CNSS | H63: Timbres mobiles | I63: CNI | J63: Extrai | K63: Amendes F | L63: Fonds d'Intervention pour l'environnement | M63: C. Adel Bagrou | N63: C. El Masgoule | O63: C. Seivane | P63: Réception de fonds | Q63: Total général
B64: =+B60 -> 0 | C64: =+C60 -> 0 | D64: =+D60 -> 0 | E64: =+E60 -> 0 | F64: =+F60 -> 0 | G64: =+G60 -> 0 | H64: =+H60 -> 0 | I64: =+I60 -> 0 | ... Q64: =+Q60 -> 0
A66: =+'RECETTES QUITT '!A20 -> Effectuée le 16/05/2024
A67: Les Auditeurs

Sheet PRECOMPTES
A1: Republique Islamique de Mauritanie | E1: Honneur-Fraternité-Justice
A2: Ministère des Finances
A3: Direction Générale du Trésor et de la Comptabilité Publique
A4: Direction de l'Audit et du Contrôle Interne
A6: Poste Comptable: Perception d'Adel Begrou
A9: Situation des Précomptes
A10: du 01/01/2024 au 15/05/2024
B12: TVA | C12: IMF | D12: ITS | E12: CNAM | F12: CNSS | G12: Total
A13: C. Adel Bagrou | B13: =+'DEP ADEL BAGROU'!G48 -> 0 | C13: =+'DEP ADEL BAGROU'!H48 -> 38400 | D13: =+'DEP ADEL BAGROU'!I48 -> 0 | E13: =+'DEP ADEL BAGROU'!J48 -> 1080 | F13: =+'DEP ADEL BAGROU'!K48 -> 270 | G13: =SUM(B13:F13) -> 39750
A14: C. El Masgoule | B14: =+'DEP El MASGOULE'!G23 -> 0 | C14: =+'DEP El MASGOULE'!H23 -> 0 | D14: =+'DEP El MASGOULE'!I23 -> 0 | E14: =+'DEP El MASGOULE'!J23 -> 0 | F14: =+'DEP El MASGOULE'!K23 -> 0 | G14: =SUM(B14:F14) -> 0
A15: C. Seivane | B15: =+'DEP SEIVANE'!G23 -> 0 | C15: =+'DEP SEIVANE'!H23 -> 0 | D15: =+'DEP SEIVANE'!I23 -> 0 | E15: =+'DEP SEIVANE'!J23 -> 0 | F15: =+'DEP SEIVANE'!K23 -> 0 | G15: =SUM(B15:F15) -> 0
A16: Total des retenus | B16: =SUM(B13:B15) -> 0 | C16: =SUM(C13:C15) -> 38400 | D16: =SUM(D13:D15) -> 0 | E16: =SUM(E13:E15) -> 1080 | F16: =SUM(F13:F15) -> 270 | G16: =SUM(G13:G15) -> 39750
A19: Précomptes Quittancés | B19: TVA | C19: IMF | D19: ITS | E19: CNAM | F19: CNSS | G19: Total
B20: =+'DEPUILLEMENT '!D64 -> 0 | C20: =+'DEPUILLEMENT '!E64 -> 0 | D20: =+'DEPUILLEMENT '!C64 -> 0 | E20: =+'DEPUILLEMENT '!F64 -> 0 | F20: =+'DEPUILLEMENT '!G64 -> 0 | G20: =SUM(B20:F20) -> 0
A22: Total CNAM et CNSS Mandaté | G22: 9720
A23: Ecart | G23: =+G16-G20+G22 -> 49470
A26: =+'RECETTES QUITT '!A20 -> Effectuée le 16/05/2024
A28: ='P V '!A44:D44 -> Les Missionnaires | F28: Le Percepteur

Sheet CNAM-CNSS
A1: N° | B1: Imputation | C1: Bénéficiaire | D1: MTTC
A2: 49 | B2: 6.1.03.2 | C2: CNAM | D2: 450
A3: 52 | B3: 6.1.03.2 | C3: CNAM | D3: 450
A4: 55 | B4: 6.1.03.2 | C4: CNAM | D4: 450
A5: 83 | B5: 6.1.03.2 | C5: CNAM | D5: 450
A6: 86 | B6: 6.1.03.2 | C6: CNAM | D6: 450
A7: 89 | B7: 6.1.03.2 | C7: CNAM | D7: 450
A8: 48 | B8: 6.1.03.1 | C8: CNSS | D8: 1170
A9: 51 | B9: 6.1.03.1 | C9: CNSS | D9: 1170
A10: 54 | B10: 6.1.03.1 | C10: CNSS | D10: 1170
A11: 82 | B11: 6.1.03.1 | C11: CNSS | D11: 1170
A12: 85 | B12: 6.1.03.1 | C12: CNSS | D12: 1170
A13: 88 | B13: 6.1.03.1 | C13: CNSS | D13: 1170
D14: =SUM(D2:D13) -> 9720

Sheet MODE REGL
B1: N° | C1: Imputation | D1: Bénéficiaire | E1: MTTC | F1: Net à Payer | G1: Mode de Règlement
A2: DRI | B2: 1834 | C2: 12304 | D2: Frais de mission | E2: Med Brahim | F2: 15000 | G2: CH2004760833
A3: ADEL B | B3: 44 | C3: 6.1.01.2 | D3: Personnel Tp | E3: 175000 | F3: 175000 | G3: CH2004760836
A4: ADEL B | B4: 60 | C4: 6.1.02.2.2 | D4: Le Maire | E4: 19500 | F4: 19500 | G4: CH2004760838
A5: ADEL B | B5: 62 | C5: 6.1.02.2.1 | D5: Le Maire | E5: 52500 | F5: 52500 | G5: CH2004760838
A6: ADEL B | B6: 63 | C6: 6.1.02.2.3 | D6: Le Maire | E6: 15960 | F6: 15960 | G6: CH2004760838
A7: SVN | B7: 5 | C7: 6.1.02.5.1 | D7: Le receveur | E7: 16000 | F7: 16000 | G7: CH2004760840
A8: SVN | B8: 6 | C8: 6.1.02.5.2 | D8: Le receveur | E8: 6000 | F8: 6000 | G8: CH2004760840
A9: ELMSGL | B9: 2 | C9: 6.1.02.5.2 | D9: Le receveur | E9: 6000 | F9: 6000 | G9: CH2004760841
A10: ELMSGL | B10: 10 | C10: 6.1.02.5.1 | D10: Le receveur | E10: 16000 | F10: 16000 | G10: CH2004760841
A11: ADEL B | B11: 67 | C11: 6.1.01.2 | D11: Personnel Tp | E11: 175000 | F11: 175000 | G11: CH2004760843
A12: ADEL B | B12: 75 | C12: 6.1.02.3.1 | D12: Adjts Aux Maire | E12: 23400 | F12: 23400 | G12: CH2004760847
A13: ADEL B | B13: 79 | C13: 6.1.02.7.2 | D13: Cheikh Med Lemine | E13: 9000 | F13: 9000 | G13: CH2004760847
A14: ADEL B | B14: 80 | C14: 6.5.02.3 | D14: Dah Taghi | E14: 39000 | F14: 37830 | G14: CH2004760847
... A45: SVN | B45: 25 | C45: 6.0.04 | D45: Ets Mzeimid | E45: 10000 | F45: 9700 | G45: CH2004760847
A46: SVN | B46: 26 | C46: 6.0.08 | D46: Ets Mzeimid | E46: 1190 | F46: 1190 | G46: CH2004760847 | J46: =323219-319217 -> 4002
A47: ADEL B | B47: 37 | C47: 6.1.02.4.1 | D47: Divers | E47: 31500 | F47: 31500 | G47: Espèce
A48: ELMSGL | B48: 1 | C48: 6.1.02.4.1 | D48: Divers | E48: 19000 | F48: 19000 | G48: Espèce
A49: SVN | B49: 9 | C49: 6.1.02.4.1 | D49: Divers | E49: 14000 | F49: 14000 | G49: Espèce
A50: DRI | B50: 6437 | C50: 27898 | D50: Apui annuel aux mahdara | E50: Divers | F50: 10000 | G50: Espèce
A51: DRI | B51: 5112 | C51: 18257 | D51: Honoraires | E51: Divers | F51: 85320 | G51: Espèce
A52: DRI | B52: 6656 | C52: 26177 | D52: Honoraires | E52: Le hakem et hakem moucaid | F52: 85320 | G52: Espèce
A53: DRI | B53: 3463 | C53: 14804 | D53: Autres achat | E53: Ets Mzeimid | F53: 100048 | G53: OV09 | H53: 45140
A54: DRI | B54: 3463 | C54: 14816 | D54: Autres achat | E54: Ets Mzeimid | F54: 112520 | G54: OV09 | H54: 45140
A55: ADEL B | B55: 47 | C55: 6.1.01.1 | D55: Personnel P | E55: 9000 | F55: 8550 | G55: OV 03/10/2023 | H55: 45202
A56: ADEL B | B56: 50 | C56: 6.1.01.1 | D56: Personnel P | E56: 9000 | F56: 8550 | G56: OV 03/10/2023 | H56: 45202
A57: ADEL B | B57: 53 | C57: 6.1.01.1 | D57: Personnel P | E57: 9000 | F57: 8550 | G57: OV 03/10/2023 | H57: 45202
A58: ADEL B | B58: 56 | C58: 6.1.01.2 | D58: Personnel Tp | E58: 36000 | F58: 36000 | G58: OV 03/10/2023 | H58: 45202
A59: ADEL B | B59: 57 | C59: 6.1.02.5.2 | D59: Le receveur | E59: 24990 | F59: 24990 | G59: OV 03/10/2023 | H59: 45202
A60: ADEL B | B60: 58 | C60: 6.1.02.7.2 | D60: Cheikhna Mousleh | E60: 9000 | F60: 9000 | G60: OV 03/10/2023 | H60: 45202
A61: ADEL B | B61: 59 | C61: 6.5.02.2 | D61: Dah Taghi | E61: 39000 | F61: 37830 | G61: OV 03/10/2023 | H61: 45202
A62: ADEL B | B62: 61 | C62: 6.1.02.3.1 | D62: Adjts Aux Maire | E62: 23400 | F62: 23400 | G62: OV 03/10/2023 | H62: 45202
A63: ADEL B | B63: 64 | C63: 6.1.02.5.1 | D63: Le receveur | E63: 24000 | F63: 24000 | G63: OV 03/10/2023 | H63: 45202
A64: DRI | B64: 3466 | C64: 14818 | D64: Honoraires | E64: Personnel CS | F64: 82800 | G64: OV10 | H64: 45140
A65: DRI | B65: 3465 | C65: 16010 | D65: Autres frais de mission et de transp | E65: Divers | F65: 99000 | G65: OV11 | H65: 45160
A66: ADEL B | B66: 45 | C66: 2.3.02 | D66: Ets Mzeimid | E66: 80480 | F66: 78065.6 | G66: OV12 | H66: 45163
A67: ADEL B | B67: 46 | C67: 2.2.02.3 | D67: Ets Mzeimid | E67: 700000 | F67: 679000 | G67: OV12 | H67: 45163
A68: DRI | B68: 4937 | C68: 18227 | D68: Autres achat | E68: Ets Mzeimid | F68: 60000 | G68: OV13 | H68: 45187
A69: DRI | B69: 4937 | C69: 18224 | D69: Autres achat | E69: Ets Mzeimid | F69: 86882.9 | G69: OV13 | H69: 45187
A70: DRI | B70: 4937 | C70: 19576 | D70: Honoraires | E70: Personnel CS | F70: 82950 | G70: OV14 | H70: 45201
...

Sheet P V 
A1: République Islamique de Mauritanie | G1: الجمهورية الإسلامية الموريتانية
A2: Honneur- Fraternité-Justice | H2: شرف-إخاء-عدالة
A3: Ministère des Finances | G3: وزارة المالية
A4: Direction Générale du Trésor et de la Comptabilité Publique | H4: المديرية العامة للخزينة و المحاسبة العمومية
A6: Direction de l'Audit et du Contrôle Interne | H6: إدارة التدقيق و الرقابة الداخلية
A9: PROCES VERBAL DE VERIFICATION DE CAISSE
A11: l'An Deux mille Vingt Quatre et le Seize Mai, nous Cheikh CHEINE et Mohamed Lemine SIDI AHMED CHEINE , respectivement Auditeur et Vérificateur à la Direction de L'Audit et du Contrôle Interne du Trésor, avons procédé suivant l'ordre de mission N°00061/2024 MF/SG/DGTCP en date du 07 Mai 2024,à la vérification de caisse de la Perception de Adel Bagrou pour la période du 01/01/2024 au 15/05/2024. Le Percepteur durant cette période étant Monsieur Eyba Mohamed OUMAR.
A17: Cette vérification a donné lieu à un arrêt comptable qui se repartit comme suit:
A19: Solde au 31/12/2023 | I19: 4096909.2
A20: Recettes du 01/01/2024 au 15/05/2024 | I20: =+'RECETTES QUITT '!D18 -> 0
A21: Total Général des Recettes | I21: =+I20+I19 -> 4096909.2
A23: Dépenses de la Commune de Adel Bagrou | I23: =+'DEP ADEL BAGROU'!E48 -> 2405680
A24: Dépenses de la Commune de El Masgoule | I24: =+'DEP El MASGOULE'!E23 -> 120600
A25: Dépenses de la Commune de Seivane | I25: =+'DEP SEIVANE'!E23 -> 98600
A26: Dépenses notifiées (en DRI) | I26: =+'DEPEN NOTIF DRI'!E50 -> 0
A27: Dégagement de fonds | I27: =+'DEG FONDS'!D18 -> 0
A28: Frais Bancaires | I28: =+'FRAIS BAN '!C16 -> 0
A29: Pensions | I29: =+PENSIONS!C19 -> 0
A30: Total Général des Dépenses du 01/01/2024 au 15/05/2024 | I30: =SUM(I23:J29) -> 2624880
A32: d’où il ressort un Solde Créditeur de | I32: =+I21-I30 -> 1472029.2
A34: Décomposition du Solde:
A35: Espèce
A36: Mauripost N°11216650121-38
A37: BMI N°10000028839
A38: Soit un total de: | I38: =SUM(I35:J37) -> 0
A39: Excédent Solde de la banque | I39: =+I32-I38 -> 1472029.2 | J39: =+I32-I38 -> 1472029.2
A41: A signé avec nous, le jour,mois et an.
C43: ='RECETTES QUITT '!A20 -> Effectuée le 16/05/2024
A44: ='RECETTES QUITT '!A22 -> Les Missionnaires | H44: Le Percepteur

Sheet SIT APPR
A1: Ministère des Finances
A2: Direction Générale du Trésor et de la Comptabilité Publique
A3: Direction de l'Audit et du Contrôle Interne
A5: Poste Comptable: Perception d'Adel Begrou
A10: Situation des Approvisionnements du 01/01/2024 au 15/05/2024
A14: Envoi | C14: Reception | F14: Ecart
A15: Date | B15: Montant | C15: Date | D15: N° Quittance | E15: Montant
F16: =B16-E16 -> 0
F17: =B17-E17 -> 0
F18: =B18-E18 -> 0
F19: =B19-E19 -> 0
A20: Total | B20: =SUM(B16:B19) -> 0 | C20: Total | E20: =SUM(E16:E19) -> 0 | F20: =E20-B20 -> 0
A25: =+'RECETTES QUITT '!A20 -> Effectuée le 16/05/2024
A27: ='P V '!A44:D44 -> Les Missionnaires | E27: Le Percepteur

Sheet RECETTES  QUITT 
A1: Ministère des Finances
A2: Direction Générale du Trésor et de la Comptabilité Publique
A3: Direction de l'Audit et du Contrôle Interne
A5: Poste Comptable: Perception d'Adel Begrou
A9: Situation des Recettes du 01/01/2024 au 15/05/2024
A13: Catégorie | B13: Debut | C13: Fin | D13: Montants
A14: Reçu de Quittance | B14: =+'DEPUILLEMENT '!A12 -> 0 | C14: =+'DEPUILLEMENT '!A59 -> 0 | D14: =+'DEPUILLEMENT '!Q60 -> 0
A18: Total Général | D18: =SUM(D14:D17) -> 0
A20: Effectuée le 16/05/2024
A22: Les Missionnaires | C22: Le Percepteur

Sheet DEG FONDS
A1: Ministère des Finances
A2: Direction Générale du Trésor et de la Comptabilité Publique
A3: Direction de l'Audit et du Contrôle Interne
A5: Poste Comptable: Perception d'Adel Begrou
A7: Situation des Dégagement des Fonds du 01/01/2024 au 15/05/2024
A9: Nature | B9: N° AD | C9: Date | D9: Montant | E9: N° AC | F9: Date | G9: Obs
A10: Chèques bancaires
B12: Total | D12: =SUM(D10:D11) -> 0
A13: Chèques du Trésor
B15: Total | D15: =SUM(D13:D14) -> 0
A16: AC
B17: Total | D17: =SUM(D16:D16) -> 0
A18: Total Général | D18: =+D12+D15+D17 -> 0
A20: =+'RECETTES QUITT '!A20 -> Effectuée le 16/05/2024
A22: ='P V '!A44:D44 -> Les Missionnaires | F22: Le Percepteur

Sheet ANNULLEE
A1: Republique Islamique de Mauritanie | C1: Honneur-Fraternité-Justice
A2: Ministère des Finances
A3: Direction Générale du Trésor et de la Comptabilité Publique
A4: Direction de l'Audit et du Contrôle Interne
A7: Poste Comptable: Perception d'Adel Begrou
A11: Situation des quittances annulées du 01/01/2024 au 15/05/2024
A14: N° Quittance | B14: Montant | C14: Motif | D14: Obsérvations
A19: =+'RECETTES QUITT '!A20 -> Effectuée le 16/05/2024
A21: ='P V '!A44:D44 -> Les Missionnaires | D21: Le Percepteur

Sheet DEPEN NOTIF DRI
A1: Republique Islamique de Mauritanie | E1: Honneur-Fraternité-Justice
A2: Ministère des Finances
A3: Direction Générale du Trésor et de la Comptabilité Publique
A4: Direction de l'Audit et du Contrôle Interne
A6: Poste Comptable: Perception d'Adel Begrou
A8: Situation des Dépenses Notifieés en DRI
A9: Pour la Période du 01/01/2024 au 15/05/2024
A10: N° Notif | B10: N° DRI | C10: l'Objet | D10: Bénéficiaire | E10: Montant Net à payer | F10: Mode de Règlement
A50: Total Général | E50: =SUM(E11:E49) -> 0
A52: =+'RECETTES QUITT '!A20 -> Effectuée le 16/05/2024
A53: ='P V '!A44:D44 -> Les Missionnaires | F53: Le Percepteur

Sheet DEP ADEL BAGROU
A1: République Islamique de Mauritanie | G1: Honneur-Fraternité-Justice
A2: Ministère et des Finances
A3: Direction Générale du Trésor et de la Comptabilité Publique
A4: Direction de l'Audit et du Contrôle Interne
A5: Poste Comptable: Perception d'Adel Begrou
A6: Situation des Dépenses de la Commune de Adel Bagrou
A7: Pour la Période du 01/01/2024 au 15/05/2024
A8: N° | B8: Imputation | C8: objet | D8: Bénéficiaire | E8: MTTC | F8: MHT | G8: TVA | H8: IMF | I8: ITS | J8: CNAM | K8: CNSS | L8: Net à Payer | M8: Mode de Règlement
A9: 4 | B9: 6.1.01.2 | C9: Personnel Temporaire Juillet au decembre 2023 | D9: PT | E9: 422000 | L9: =+E9-G9-H9-I9-J9-K9 -> 422000 | M9: CH 4760850 LE 14/02
A10: 5 | B10: 6.1.02.4.1 | C10: Indemnités de sessions jan 2024 | D10: C MUNICIPAL | E10: 36000 | L10: =+E10-G10-H10-I10-J10-K10 -> 36000 | M10: CH 4760839 LE 28/02
A11: 6 | B11: 6.0.15 | C11: Carburants et Lubrifiants | D11: ETS MZEIMID | E11: 210000 | L11: =+E11-G11-H11-I11-J11-K11 -> 210000 | M11: VRT 03/2024 DU 14/02
A12: 8 | B12: 6.1.01.2 | C12: Personnel Temporaire Janv 2024 | D12: PT | E12: 54000 | L12: =+E12-G12-H12-I12-J12-K12 -> 54000 | M12: CH 4760839 LE 28/02
A13: 9 | B13: 6.1.02.2.2 | C13: Indemnités de Fonction jan fev mars | D13: Le Maire | E13: 19500 | L13: =+E13-G13-H13-I13-J13-K13 -> 19500 | M13: CH 2005073002 LE 16/04
A14: 10 | B14: 6.1.02.3.1 | C14: Indemnités de Fonction jan fev mars | D14: Le Maire Adjoint | E14: 23400 | L14: =+E14-G14-H14-I14-J14-K14 -> 23400 | M14: VRT 05/24 LE 08/04
A15: 11 | B15: 6.1.02.2.1 | C15: Indemnités de Répresentation jan fev mars | D15: Le Maire | E15: 52500 | L15: =+E15-G15-H15-I15-J15-K15 -> 52500 | M15: CH 2005073002 LE 16/04
A16: 12 | B16: 6.1.02.2.3 | C16: Indemnités Comp du log janv fev mars | D16: Le Maire | E16: 15960 | L16: =+E16-G16-H16-I16-J16-K16 -> 15960 | M16: CH 2005073002 LE 16/04
A17: 13 | B17: 6.1.02.5.1 | C17: Indémnités de gestion comptable jan fev mars | D17: RM | E17: 24000 | L17: =+E17-G17-H17-I17-J17-K17 -> 24000 | M17: CH 0849
A18: 14 | B18: 6.1.02.7.2 | C18: Autres Primes | D18: Cheikh med lemine MAIRE ADJOINT | E18: 9000 | L18: =+E18-G18-H18-I18-J18-K18 -> 9000 | M18: VRT 05/24 LE 08/04
A19: 15 | B19: 6.1.02.7.2 | C19: Autres Primes | D19: Neny Mahfoudh | E19: 39000 | L19: =+E19-G19-H19-I19-J19-K19 -> 39000 | M19: CH 2005073004 LE 15/04
A20: 16 | B20: 6.1.02.5.2 | C20: Prime de rendement comptable jan fev mars | D20: RM | E20: 25500 | L20: =+E20-G20-H20-I20-J20-K20 -> 25500 | M20: CH 2005073002 LE 01/04
A21: 17 | B21: 6.1.01.2 | C21: Personnel Temporaire Jan fev mars | D21: PT | E21: 51000 | L21: =+E21-G21-H21-I21-J21-K21 -> 51000 | M21: VRT 05 ET CH 73004 ET ESP
A22: 19 | B22: 6.1.01.1 | C22: Personnel Permanent Janv | D22: pp | E22: 9000 | J22: 360 | K22: 90 | L22: =+E22-G22-H22-I22-J22-K22 -> 8550 | M22: VRT 05 LE 08/04
A23: 20 | B23: 6.1.03.1 | C23: Part Patronale Sec Soc | D23: CNSS | E23: =L23 -> 1170 | L23: 1170 | M23: QUITT
A24: 21 | B24: 6.1.03.2 | C24: Part Patronale Assur maladie | D24: CNAM | E24: =L24 -> 450 | L24: 450 | M24: QUITT
A25: 22 | B25: 6.1.01.1 | C25: Personnel Permanent Fev | D25: pp | E25: 9000 | J25: 360 | K25: 90 | L25: =+E25-G25-H25-I25-J25-K25 -> 8550 | M25: VRT 05 LE 08/04
A26: 23 | B26: 6.1.03.1 | C26: Part Patronale Sec Soc | D26: CNSS | E26: =L26 -> 1170 | L26: 1170
A27: 24 | B27: 6.1.03.2 | C27: Part Patronale Assur maladie | D27: CNAM | E27: =L27 -> 450 | L27: 450
A28: 25 | B28: 6.1.01.1 | C28: Personnel Permanent Mars | D28: pp | E28: 9000 | J28: 360 | K28: 90 | L28: =+E28-G28-H28-I28-J28-K28 -> 8550 | M28: VRT 05 LE 08/04
A29: 26 | B29: 6.1.03.1 | C29: Part Patronale Sec Soc | D29: CNSS | E29: =L29 -> 1170 | L29: 1170
A30: 27 | B30: 6.1.03.2 | C30: Part Patronale Assur maladie | D30: CNAM | E30: =L30 -> 450 | L30: 450
A31: 74 | B31: 6.1.02.2.2 | C31: Indemnités de Fonction oct nov dec 2023 JOURNEES COMPL | D31: LE Maire | E31: 19500 | L31: =+E31 -> 19500 | M31: CH 4760848 LE 06.02.2024
A32: 76 | B32: 6.1.02.2.1 | C32: Indémnités de Répresentation oct nov dec 2023 | D32: LE Maire | E32: 52500 | L32: =+E32-G32-H32-I32-J32-K32 -> 52500 | M32: CH 4760848 LE 06.02.2025
A33: 77 | B33: 6.1.02.2.3 | C33: Indémnités Comp du log oct nov dec 2024 | D33: LE Maire | E33: 15960 | L33: =+E33-G33-H33-I33-J33-K33 -> 15960 | M33: CH 4760848 LE 06.02.2025
A34: 78 | B34: 6.1.02.5.1 | C34: Indémnités de gestion comptable oct nov dec | D34: RM | E34: 24000 | L34: =+E34-G34-H34-I34-J34-K34 -> 24000 | M34: CH 2005073002 LE 01/04
A35: Total des Dépenses de Fonctionnement | E35: =SUM(E9:E34) -> 1125680 | F35: =SUM(F9:F34) -> 0 | G35: =SUM(G9:G34) -> 0 | H35: =SUM(H9:H34) -> 0 | I35: =SUM(I9:I34) -> 0 | J35: =SUM(J9:J34) -> 1080 | K35: =SUM(K9:K34) -> 270 | L35: =SUM(L9:L34) -> 1124330
A36: 1 | B36: 2.1.01 | C36: Subventions d’equip versé | D36: ETS EMEL | E36: 375000 | H36: =+E36*0.03 -> 11250 | L36: =+E36-G36-H36-I36-J36-K36 -> 363750 | M36: VRT 02/2024 DU 14/02
A37: 2 | B37: 2.1.01 | C37: Subventions d’equip versé | D37: ETS EMEL | E37: 240000 | H37: =+E37*0.03 -> 7200 | L37: =+E37-G37-H37-I37-J37-K37 -> 232800 | M37: VRT 02/2024 DU 14/02
A38: 3 | B38: 2.1.01 | C38: Subventions d’equip versé | D38: ETS EMZEIMID | E38: 370000 | H38: =+E38*0.03 -> 11100 | L38: =+E38-G38-H38-I38-J38-K38 -> 358900 | M38: VRT 01/2024 DU 14/02
A39: 7 | B39: 2.2.01.5.3 | C39: Assainissement | D39: ETS EMZEIMID | E39: 295000 | H39: =+E39*0.03 -> 8850 | L39: =+E39-G39-H39-I39-J39-K39 -> 286150 | M39: VRT 03/2024 DU 14/02
L40: =+E31-G40-H40-I40-J40-K40 -> 19500
...

Sheet  RECETTE ADEL BAGROU
A1: Republique Islamique de Mauritanie | D1: Honneur-Fraternité-Justice
A2: Ministère des Finances
A3: Direction Générale du Trésor et de la Comptabilité Publique
A4: Direction de l'Audit et du Contrôle Interne
A6: Poste Comptable: Perception d'Adel Begrou
A11: Situation des Recettes de la Commune de Adel Bagrou
A12: Pour la Période du 01/01/2024 au 15/05/2024
A13: N° | B13: Imputation | C13: N° Quittance | D13: Nature | E13: Montant
A14: 4 | B14: 7.1.05 | D14: PATENTE | E14: 10000
A15: 5 | B15: 7.1.05 | C15: 2024T00224000005 | D15: PATENTE | E15: 15000
A16: 6 | B16: 7.1.05 | C16: 2024T00224000012 | D16: PATENTE | E16: 222857
A20: Total des Recttes de Fonctionnement | E20: =SUM(E14:E19) -> 247857
A23: Total des Recttes d'Equippement | E23: =SUM(E21:E22) -> 0
A25: Total Général | E25: =+E20+E23 -> 247857
A28: =+'RECETTES QUITT '!A20 -> Effectuée le 16/05/2024
A30: ='P V '!A44:D44 -> Les Missionnaires | C30: Le Maire | E30: Le Receveur municipal

Sheet DISP ADEL BAGROU
A1: Republique Islamique de Mauritanie | E1: Honneur-Fraternité-Justice
A2: Ministère des Finances
A3: Direction Générale du Trésor et de la Comptabilité Publique
A4: Direction de l'Audit et du Contrôle Interne
A6: Poste Comptable: Perception d'Adel Begrou
A8: Situation du Disponible au 31/12/2023
A9: COMMUNE DE ADEL BAGROU
A10: Disponible de Fonctionnement au 31/12/2023 | F10: 2075883
A12: Recettes de Fonctionnement du 01/01 au 15/05/2024 | F12: =+' RECETTE ADEL BAGROU'!E20 -> 247857
A13: Dépenses de Fonctionnement du 01/01 au 15/05/2024 | F13: =+'DEP ADEL BAGROU'!E35 -> 1125680
A15: Disponible de Fonctionnement au 31/12/2023 | F15: =+F10+F12-F13 -> 1198060
A17: Disponible d'équippement au 31/12/2023 | F17: 4758061
A19: Recettes d'équippement du 01/01 au 15/05/2024 | F19: =+' RECETTE ADEL BAGROU'!E23 -> 0
A20: Dépenses d'équippement du 01/01 au 15/05/2024
A22: Disponible d'équippement au 31/12/2023 | F22: =+F17+F19-F20 -> 4758061
A24: Total Général | F24: =+F15+F22 -> 5956121
A27: =+'RECETTES QUITT '!A20 -> Effectuée le 16/05/2024
A29: ='P V '!A44:D44 -> Les Missionnaires | C29: Le Maire | F29: Le Receveur municipal

Sheet  RECETTE El MASGOULE
A1: Republique Islamique de Mauritanie | D1: Honneur-Fraternité-Justice
A2: Ministère des Finances
A3: Direction Générale du Trésor et de la Comptabilité Publique
A4: Direction de l'Audit et du Contrôle Interne
A6: Poste Comptable: Perception d'Adel Begrou
A9: Situation des Recettes de la Commune de El Masgoule
A10: Pour la Période du 01/01/2024 au 15/05/2024
A12: N° | B12: Imputation | C12: N° Quittance | D12: Nature | E12: Montant
A13: 1 | B13: 7.1.05 | D13: PATENTE | E13: 113043
A14: 2 | B14: 7.1.05 | D14: PATENTE | E14: 11000
A15: Total des Recttes de Fonctionnement | E15: =SUM(E13:E14) -> 124043
A17: Total des Recttes d'Equippement | E17: =SUM(E16:E16) -> 0
A19: Total Général | E19: =+E15+E17 -> 124043
A23: =+'RECETTES QUITT '!A20 -> Effectuée le 16/05/2024
A25: ='P V '!A44:D44 -> Les Missionnaires | C25: Le Maire | E25: Le Receveur municipal

Sheet DEP El MASGOULE
A1: République Islamique de Mauritanie | G1: Honneur-Fraternité-Justice
A2: Ministère et des Finances
A3: Direction Générale du Trésor et de la Comptabilité Publique
A4: Direction de l'Audit et du Contrôle Interne
A5: Poste Comptable: Perception d'Adel Begrou
A6: Situation des Dépenses de la Commune de El Masgoule
A7: Pour la Période du 01/01/2024 au 15/05/2024
A8: N° | B8: Imputation | C8: OJBET | D8: BENEFICIAIRE | E8: MTTC | F8: MHT | G8: TVA | H8: IMF | I8: ITS | J8: CNAM | K8: CNSS | L8: Net à Payer | M8: Mode de Règlement
A9: 1 | B9: 6.1.02.2.2 | C9: Indemnités de fonction janv fev mars | D9: LE Maire | E9: 8100 | L9: =E9-G9-H9-J9-K9-I9 -> 8100 | M9: VRT 07 LE 17/04
A10: 2 | B10: 6.1.02.3.1 | C10: Indemnités de fonction janv fev mars | D10: LE Maire Adjoint | E10: 4500 | L10: =E10-G10-H10-J10-K10-I10 -> 4500 | M10: VRT 07 LE 17/04
A11: 3 | B11: 6.1.02.2.1 | C11: Indemnités de Répresentation janv fev mars | D11: LE Maire | E11: 10500 | L11: =E11-G11-H11-J11-K11-I11 -> 10500 | M11: VRT 07 LE 17/04
A12: 4 | B12: 6.1.02.2.3 | C12: Indemnités comp du mlog janv fev mars | D12: LE Maire | E12: 9000 | L12: =E12-G12-H12-J12-K12-I12 -> 9000 | M12: VRT 07 LE 17/04
A13: 5 | B13: 6.1.02.5.1 | C13: Indemnités comp du log janv fev mars | D13: RM | E13: 12000 | L13: =E13-G13-H13-J13-K13-I13 -> 12000 | M13: VRT 07 LE 17/04
A14: 6 | B14: 6.1.02.5.2 | C14: Prime de rendement | D14: RM | E14: 4500 | L14: =E14-G14-H14-J14-K14-I14 -> 4500 | M14: VRT 07 LE 17/04
A15: 7 | B15: 6.1.02.7.2 | C15: Autres primes | D15: neny mahfoudh | E15: 12000 | L15: =E15-G15-H15-J15-K15-I15 -> 12000 | M15: VRT 07 LE 17/04
A16: 8 | B16: 6.1.02.6.1 | C16: Indemnités de fonction janv fev mars | D16: SG | E16: 12000 | L16: =E16-G16-H16-J16-K16-I16 -> 12000 | M16: VRT 07 LE 17/04
A17: 9 | B17: 6.1.01.2 | C17: Personnel Temporaire janv fev mars | D17: PT | E17: 36000 | L17: =E17-G17-H17-J17-K17-I17 -> 36000 | M17: CH 2005073007
A18: 10 | B18: 6.1.01.2 | C18: Personnel Temporaire janv fev mars | D18: PT | E18: 12000 | L18: =E18-G18-H18-J18-K18-I18 -> 12000 | M18: CH 2005073007
A19: Total des Dépenses de Fonctionnement | E19: =SUM(E9:E18) -> 120600 | F19: =SUM(F9:F18) -> 0 | G19: =SUM(G9:G18) -> 0 | H19: =SUM(H9:H18) -> 0 | I19: =SUM(I9:I18) -> 0 | J19: =SUM(J9:J18) -> 0 | K19: =SUM(K9:K18) -> 0 | L19: =SUM(L9:L18) -> 120600
L20: =E20-G20-H20-J20-K20-I20 -> 0
A21: Total des Dépenses d'équippement | E21: =SUM(E20:E20) -> 0 | F21: =SUM(F20:F20) -> 0 | G21: =SUM(G20:G20) -> 0 | H21: =SUM(H20:H20) -> 0 | I21: =SUM(I20:I20) -> 0 | J21: =SUM(J20:J20) -> 0 | K21: =SUM(K20:K20) -> 0 | L21: =SUM(L20:L20) -> 0
A23: TOTAL GENERAL DES DEPENSES | E23: =+E19+E21 -> 120600 | F23: =+F19+F21 -> 0 | G23: =+G19+G21 -> 0 | H23: =+H19+H21 -> 0 | I23: =+I19+I21 -> 0 | J23: =+J19+J21 -> 0 | K23: =+K19+K21 -> 0 | L23: =+L19+L21 -> 120600
A25: =+'RECETTES QUITT '!A20 -> Effectuée le 16/05/2024
A26: ='P V '!A44:D44 -> Les Missionnaires | E26: Le Maire | K26: Le Receveur municipal

Sheet DISP El MASGOULE
A1: Ministère des Finances
A2: Direction Générale du Trésor et de la Comptabilité Publique
A3: Direction de l'Audit et du Contrôle Interne
A5: Poste Comptable: Perception d'Adel Begrou
A7: Situation du Disponible au 15/05/2024
A8: COMMUNE DE El MASGOULE
A9: Disponible de Fonctionnement au 31/12/2023 | F9: 33508
A11: Recettes de Fonctionnement du 01/01 au 15/05/2024 | F11: =+' RECETTE El MASGOULE'!E15 -> 124043
A12: Dépenses de Fonctionnement du 01/01 au 15/05/2024 | F12: =+'DEP El MASGOULE'!E19 -> 120600
A14: Disponible de Fonctionnement au 15/05/2024 | F14: =+F9+F11-F12 -> 36951
A16: Disponible d'équippement au 31/12/2023 | F16: 304
A18: Recettes d'équippement du 01/01 au 15/05/2024 | F18: =+' RECETTE El MASGOULE'!E17 -> 0
A19: Dépenses d'équippement du 01/01 au 15/05/2024 | F19: =+'DEP El MASGOULE'!E21 -> 0
A21: Disponible d'équippement au 15/05/2024 | F21: =+F16+F18-F19 -> 304
A23: Total Général | F23: =+F14+F21 -> 37255
A26: =+'RECETTES QUITT '!A20 -> Effectuée le 16/05/2024
A28: =' RECETTE El MASGOULE'!A25 -> Les Missionnaires | C28: Le Maire | F28: Le Receveur municipal

Sheet  RECETTE SEIVANE
A1: Ministère des Finances
A2: Direction Générale du Trésor et de la Comptabilité Publique
A3: Direction de l'Audit et du Contrôle Interne
A5: Poste Comptable: Perception d'Adel Begrou
A10: Situation des Recettes de la Commune de Seivane
A11: Pour la Période du 01/01/2024 au 15/05/2024
A13: N° | B13: Imputation | C13: N° Quittance | D13: Nature | E13: Montant
A14: 1 | B14: 7.1.05 | C14: 2024T00224000014 | D14: PATENTE | E14: 113043
A15: 2 | B15: 7.1.05 | C15: 2024T00224000007 | D15: PATENTE | E15: 11000
A16: Total des Recttes de Fonctionnement | E16: =SUM(E14:E15) -> 124043
A18: Total des Recttes d'Equippement | E18: =SUM(E17:E17) -> 0
A20: Total Général | E20: =+E16+E18 -> 124043
A24: =+'RECETTES QUITT '!A20 -> Effectuée le 16/05/2024
A26: =' RECETTE El MASGOULE'!A25 -> Les Missionnaires | C26: Le Maire | E26: Le Receveur municipal

Sheet DEP SEIVANE
A1: Ministère et des Finances
A2: Direction Générale du Trésor et de la Comptabilité Publique
A3: Direction de l'Audit et du Contrôle Interne
A5: Poste Comptable: Perception d'Adel Begrou
A7: Situation des Dépenses de la Commune de Seivane
A8: Pour la Période du 01/01/2024 au 15/05/2024
A9: N° | B9: Imputation | C9: OBJET | D9: Bénéficiaire | E9: MTTC | F9: MHT | G9: TVA | H9: IMF | I9: ITS | J9: CNAM | K9: CNSS | L9: Net à Payer | M9: Mode de Règlement
A10: 1 | B10: 6.1.02.2.2 | C10: Indemnités de fonction janv fev mars | D10: le Maire | E10: 8100 | L10: =E10-G10-H10-J10-K10-I10 -> 8100 | M10: VRT 06 DU 08/04
A11: 2 | B11: 6.1.02.3.1 | C11: Indemnités de fonction janv fev mars | D11: MAIRE ADJOINT | E11: 4500 | L11: =E11-G11-H11-J11-K11-I11 -> 4500 | M11: VRT 06 DU 08/04
A12: 3 | B12: 6.1.02.2.1 | C12: Indemnités de Representation janv fev mars | D12: le Maire | E12: 10500 | L12: =E12-G12-H12-J12-K12-I12 -> 10500 | M12: VRT 06 DU 08/04
A13: 4 | B13: 6.1.02.2.3 | C13: Indem comp du log | D13: le Maire | E13: 9000 | L13: =E13-G13-H13-J13-K13-I13 -> 9000 | M13: VRT 06 DU 08/04
A14: 5 | B14: 6.1.02.5.1 | C14: Indem de gestion compt janv à mars | D14: RM | E14: 12000 | L14: =E14-G14-H14-J14-K14-I14 -> 12000 | M14: VRT 06 DU 08/04
A15: 6 | B15: 6.1.02.5.2 | C15: Prime rendement janv fev mars | D15: RM | E15: 4500 | L15: =E15-G15-H15-J15-K15-I15 -> 4500 | M15: VRT 06 DU 08/04
A16: 7 | B16: 6.1.02.7.2 | C16: Autres primes | D16: Neny mahfoudh | E16: 12000 | L16: =E16-G16-H16-J16-K16-I16 -> 12000 | M16: VRT 06 DU 08/04
A17: 8 | B17: 6.1.02.4.1 | C17: Indemnités de sessions | D17: CM | E17: 11000 | L17: =E17-G17-H17-J17-K17-I17 -> 11000 | M17: CH 2005073006
A18: 9 | B18: 6.1.01.2 | C18: Personnel Temporaire janv fev mars | D18: PT | E18: 27000 | L18: =E18-G18-H18-J18-K18-I18 -> 27000 | M18: VRT 06 DU 08/04
A19: Total des Dépenses de Fonctionnement | E19: =SUM(E10:E18) -> 98600 | F19: =SUM(F10:F18) -> 0 | G19: =SUM(G10:G18) -> 0 | H19: =SUM(H10:H18) -> 0 | I19: =SUM(I10:I18) -> 0 | J19: =SUM(J10:J18) -> 0 | K19: =SUM(K10:K18) -> 0 | L19: =SUM(L10:L18) -> 98600
L20: =E20-G20-H20-J20-K20-I20 -> 0
A21: Total des Dépenses d'équippement | E21: =SUM(E20:E20) -> 0 | F21: =SUM(F20:F20) -> 0 | G21: =SUM(G20:G20) -> 0 | H21: =SUM(H20:H20) -> 0 | I21: =SUM(I20:I20) -> 0 | J21: =SUM(J20:J20) -> 0 | K21: =SUM(K20:K20) -> 0 | L21: =SUM(L20:L20) -> 0
A23: TOTAL GENERAL DES DEPENSES | E23: =+E19+E21 -> 98600 | F23: =+F19+F21 -> 0 | G23: =+G19+G21 -> 0 | H23: =+H19+H21 -> 0 | I23: =+I19+I21 -> 0 | J23: =+J19+J21 -> 0 | K23: =+K19+K21 -> 0 | L23: =+L19+L21 -> 98600
A25: =+'RECETTES QUITT '!A20 -> Effectuée le 16/05/2024
A26: =' RECETTE El MASGOULE'!A25 -> Les Missionnaires | E26: Le Maire | K26: Le Receveur municipal

Sheet DISP SEIVANE
A1: Ministère des Finances
A2: Direction Générale du Trésor et de la Comptabilité Publique
A3: Direction de l'Audit et du Contrôle Interne
A5: Poste Comptable: Perception d'Adel Begrou
A7: Situation du Disponible au 15/05/2024
A8: COMMUNE DE SEIVANE
A9: Disponible de Fonctionnement au 31/12/2023 | F9: 7165
A11: Recettes de Fonctionnement du 01/01 au 15/05/2024 | F11: =+' RECETTE SEIVANE'!E16 -> 124043
A12: Dépenses de Fonctionnement du 01/01 au 15/05/2024 | F12: =+'DEP SEIVANE'!E19 -> 98600
A14: Disponible de Fonctionnement au 15/05/2024 | F14: =+F9+F11-F12 -> 32608
A16: Disponible d'équippement au 31/12/2023 | F16: 9
A18: Recettes d'équippement du 01/01 au 15/05/2024 | F18: =+' RECETTE SEIVANE'!E18 -> 0
A19: Dépenses d'équippement du 01/01 au 15/05/2024 | F19: =+'DEP SEIVANE'!E21 -> 0
A21: Disponible d'équippement au 15/05/2024 | F21: =+F16+F18-F19 -> 9
A23: Total Général | F23: =+F14+F21 -> 32617
A26: =+'RECETTES QUITT '!A20 -> Effectuée le 16/05/2024
A28: =' RECETTE SEIVANE'!A26 -> Les Missionnaires | C28: Le Maire | F28: Le Receveur municipal

Sheet REJETS
A1: Ministère des Finances
A2: Direction Générale du Trésor et de la Comptabilité Publique
A3: Direction de l'Audit et du Contrôle Interne
A5: Poste Comptable: Perception d'Adel Begrou
A7: Les Rejets du 01/01/2024 au 15/05/2024
A11: N°AD | B11: Date | C11: N° AC | D11: Montant | E11: N° Quittance
A13: Total | D13: =SUM(D12) -> 0
A16: =+'RECETTES QUITT '!A20 -> Effectuée le 16/05/2024
A18: =' RECETTE SEIVANE'!A26 -> Les Missionnaires | E18: Le Percepteur

Sheet FRAIS BAN 
A1: Ministère des Finances
A2: Direction Générale du Trésor et de la Comptabilité Publique
A3: Direction de l'Audit et du Contrôle Interne du Trésor
A5: Poste Comptable: Perception d'Adel Begrou
A9: Situation des Charges Bancaires et Agios du 01/01/2024 au 15/05/2024
A11: Période | B11: Banque | C11: Montant
A12: du 01/01/2024 au 15/05/2024 | B12: BMI (Moudoun)
B14: MAURIPOST
A16: Total | C16: =SUM(C12:C15) -> 0
A19: =+'RECETTES QUITT '!A20 -> Effectuée le 16/05/2024
A22: ='P V '!A44:D44 -> Les Missionnaires | C22: Le Percepteur

Sheet H CAISSE
A1: Ministère des Finances
A2: Direction Générale du Trésor et de la Comptabilité Publique
A3: Direction de l'Audit et du Contrôle Interne
A4: Poste Comptable: Perception d'Adel Begrou
A6: Situation des Hors Caisse 2023 au 15/05/2024
A9: I- Mahdra 2023
A11: N° liste | B11: Bénéficiaire | D11: Montant
A12: 1 | B12: Sid Ahmed Ebi | D12: 1000
A13: 3 | B13: Heida Yemehlou | D13: 2000
A14: 5 | B14: Sid Ahmed Beih | D14: 1000
A15: 7 | B15: Naji Boune | D15: 1000
A16: Total 1 | D16: =SUM(D12:D15) -> 5000
A18: II - Subventions des Mosquées 2023
A20: Nombre | B20: Bénéficiaire | C20: Montant | D20: Montant total
D21: =+A21*C21 -> 0
A22: Total 2 | D22: =SUM(D21:D21) -> 0
A25: Total Général | D25: =+D16+D22 -> 5000
A27: =+'RECETTES QUITT '!A20 -> Effectuée le 16/05/2024
A28: ='FRAIS BAN '!A22 -> Les Missionnaires | D28: Le Percepteur

Sheet PENSIONS
A1: Ministère des Finances
A2: Direction Générale du Trésor et de la Comptabilité Publique
A3: Direction de l'Audit et du Contrôle Interne
A5: Poste Comptable: Perception d'Adel Begrou
A8: Situation des Pensions du 01/01/2024 au 15/05/2024
A10: N° Pension | B10: Nom | C10: Montant | D10: Mode de reglement
A19: Total | C19: =SUM(C11:C18) -> 0
A21: =+'RECETTES QUITT '!A20 -> Effectuée le 16/05/2024
A23: ='FRAIS BAN '!A22 -> Les Missionnaires | D23: Le Percepteur

Sheet CAC ADEL BAGROU
A1: Ministère des Finances
A2: Direction Générale du Trésor et de la Comptabilité Publique
A3: Direction de l'Audit et du Contrôle Interne
A5: Poste Comptable: Perception d'Adel Begrou
A9: Etat de Rapprochement Recettes de l'Etat Civil (CAC Adel Bgrou) du 01/01/2024 au 15/05/2024
A11: Date | B11: N° Quittance | C11: CNI | D11: Actes et Extrait
A20: Total | C20: =SUM(C12:C19) -> 0 | D20: =SUM(D12:D19) -> 0
A22: =+'RECETTES QUITT '!A20 -> Effectuée le 16/05/2024
A23: ='FRAIS BAN '!A22 -> Les Missionnaires | C23: Le Chef de Centre | D23: Le Percepteur

Sheet RAP AF GM
A1: Ministère des Finances
A2: Direction Générale du Trésor et de la Comptabilité Publique
A3: Direction de l'Audit et du Contrôle Interne
A5: Poste Comptable: Perception d'Adel Begrou
A8: Etat de Rapprochement Recettes des amendes de la Compagnie de la Gendarmerie Nationale
A9: du 01/01/2024 au 15/05/2024
A11: Date | B11: N° Quittance | C11: Montant | D11: Brigade
A18: Total | C18: =SUM(C12:C17) -> 0
A20: =+'RECETTES QUITT '!A20 -> Effectuée le 16/05/2024
A22: ='H CAISSE'!A28 -> Les Missionnaires | B22: Le Cdt de Campagnie | D22: Le Percepteur
